{
  "id": "thought_1741686876",
  "timestamp": "2025-03-11T17:54:36.882579",
  "original_filename": "test_thought_2.txt",
  "original_path": "/Volumes/Samsung/users/brad/Library/Mobile Documents/iCloud~md~obsidian/Documents/Digital Alchemy/1-Capture/test_thought_2.txt",
  "content": "Dummy thought content for Digital Alchemy system.\n",
  "processing_stage": "connect",
  "processing_history": [
    {
      "stage": "capture",
      "timestamp": "2025-03-11T17:54:36.882677"
    },
    {
      "stage": "capture",
      "timestamp": "2025-03-11T17:54:36.901130"
    },
    {
      "stage": "contextualize",
      "timestamp": "2025-03-11T17:54:36.904971"
    },
    {
      "stage": "clarify",
      "timestamp": "2025-03-11T17:54:36.907818"
    },
    {
      "stage": "categorize",
      "timestamp": "2025-03-11T17:54:36.911238"
    },
    {
      "stage": "crystallize",
      "timestamp": "2025-03-11T17:54:36.914410"
    }
  ],
  "capture_results": "ERROR: Failed to communicate with LLM: HTTPConnectionPool(host='localhost', port=11434): Max retries exceeded with url: /api/generate (Caused by NewConnectionError('<urllib3.connection.HTTPConnection object at 0x1218eb5e0>: Failed to establish a new connection: [Errno 61] Connection refused'))",
  "contextualize_results": "ERROR: Failed to communicate with LLM: HTTPConnectionPool(host='localhost', port=11434): Max retries exceeded with url: /api/generate (Caused by NewConnectionError('<urllib3.connection.HTTPConnection object at 0x1218bbb20>: Failed to establish a new connection: [Errno 61] Connection refused'))",
  "clarify_results": "ERROR: Failed to communicate with LLM: HTTPConnectionPool(host='localhost', port=11434): Max retries exceeded with url: /api/generate (Caused by NewConnectionError('<urllib3.connection.HTTPConnection object at 0x1218eafe0>: Failed to establish a new connection: [Errno 61] Connection refused'))",
  "categorize_results": "ERROR: Failed to communicate with LLM: HTTPConnectionPool(host='localhost', port=11434): Max retries exceeded with url: /api/generate (Caused by NewConnectionError('<urllib3.connection.HTTPConnection object at 0x1218f8340>: Failed to establish a new connection: [Errno 61] Connection refused'))",
  "crystallize_results": "ERROR: Failed to communicate with LLM: HTTPConnectionPool(host='localhost', port=11434): Max retries exceeded with url: /api/generate (Caused by NewConnectionError('<urllib3.connection.HTTPConnection object at 0x1218f8970>: Failed to establish a new connection: [Errno 61] Connection refused'))",
  "connect_results": "ERROR: Failed to communicate with LLM: HTTPConnectionPool(host='localhost', port=11434): Max retries exceeded with url: /api/generate (Caused by NewConnectionError('<urllib3.connection.HTTPConnection object at 0x1218f9000>: Failed to establish a new connection: [Errno 61] Connection refused'))"
}